Traceback (most recent call last):
  File "/home/pranavsatheesh/host_galaxies/py_files/population_sort_mergers_and_non_mergers.py", line 346, in <module>
    print(f"Creating merger and non merger populations for sim run"+basePath.split("/")[-2])
  File "/home/pranavsatheesh/host_galaxies/py_files/population_sort_mergers_and_non_mergers.py", line 292, in save_population_to_file
    outfilename = save_path + f'/{self.simName}_population_sort_gas-{self.minN_values[0]:03d}_dm-{self.minN_values[1]:03d}_star-{self.minN_values[2]:03d}_bh-{self.minN_values[3]:03d}.hdf5'
  File "/blue/lblecha/pranavsatheesh/.conda/envs/hfrl/lib/python3.10/site-packages/h5py/_hl/files.py", line 561, in __init__
    fid = make_fid(name, mode, userblock_size, fapl, fcpl, swmr=swmr)
  File "/blue/lblecha/pranavsatheesh/.conda/envs/hfrl/lib/python3.10/site-packages/h5py/_hl/files.py", line 241, in make_fid
    fid = h5f.create(name, h5f.ACC_TRUNC, fapl=fapl, fcpl=fcpl)
  File "h5py/_objects.pyx", line 54, in h5py._objects.with_phil.wrapper
  File "h5py/_objects.pyx", line 55, in h5py._objects.with_phil.wrapper
  File "h5py/h5f.pyx", line 122, in h5py.h5f.create
BlockingIOError: [Errno 11] Unable to synchronously create file (unable to lock file, errno = 11, error message = 'Resource temporarily unavailable')
